<!-- Very simple example of a robot with one continuous joint using the analogue pin 0 from
     a RoNeX GeneralIO module to set the current position of the joint. -->
<robot name="test_robot">
  <link name="link1" />
  <link name="link2" />

  <joint name="joint1" type="continuous">
    <parent link="link1"/>
    <child link="link2"/>
  </joint>

 <!-- transmission type="sr_ronex_transmissions/RonexTransmission" name="my_ronex_transmission">
    <joint name="joint1"/>
    <mapping ronex="/ronex/0" property="position" analogue_pin="6" scale="1.0" offset="0.0"/>
    <mapping ronex="/ronex/0" property="effort"   analogue_pin="7" scale="2.0" offset="1.0"/>
    <mapping ronex="/ronex/0" property="command" pwm_module="3" pwm_pin="0"/>
  </transmission -->
</robot>
